Workbook

Sheet Mode d'emploi
B1: PROSPECTION GRANDES ECOLES - INITIATION A L'IA
B3: Onglet | C3: A quoi il sert
B4: Suivi appels | C4: LA feuille de travail. Une ligne par ecole. C'est le seul onglet a remplir.
B5: Tableau de bord | C5: Se calcule tout seul depuis Suivi appels. Ne rien y saisir.
B6: Base contacts | C6: La fiche complete de chaque ecole : adresse, 2e numero, site, source, fiabilite.
B7: Offre et tarifs | C7: Ce qui est vendu et a quel prix. Le tableau de CA se recalcule si on change un montant.
B8: Scripts et objections | C8: Quoi dire en WhatsApp, au telephone, par mail, et quoi repondre aux objections.
B10: Colonnes a remplir (fond jaune)
B11: Nom du Directeur des Etudes | C11: A demander des le premier appel au standard. C'est l'information qui manque et qui fera la valeur de cette base.
B12: Date 1er contact | C12: Format JJ/MM/AAAA.
B13: Statut | C13: Liste deroulante. Fait vivre le tableau de bord.
B14: Montant par eleve | C14: 5000 ou 10000 FCFA. C'est l'etablissement qui le fixe.
B15: Nb eleves par classe | C15: Effectif reel qui paiera. Seuil de rentabilite : 20.
B16: Nb seances negocie | C16: 1 par defaut. Passer a 2 seulement si la 2e seance a ete negociee.
B17: Nb classes | C17: Nombre de classes engagees par l'etablissement.
B18: Date seance | C18: Format JJ/MM/AAAA.
B20: Colonne calculee (fond vert)
B21: Montant attendu | C21: =(montant par eleve + supplement) x nb eleves x nb classes.
C22: Supplement applique : +3 000 FCFA par eleve si une 2e seance est negociee au palier 5 000.
C23: Au palier 10 000, la 2e seance est incluse : aucun supplement. Regle definie dans Offre et tarifs.
B25: Avertissement sur les numeros
C26: Les numeros en fiabilite Moyenne viennent d'annuaires et n'ont pas ete verifies un par un.
C27: Les anciens numeros a 8 chiffres ont ete convertis au format post-2021. En cas d'echec, essayer le 2e numero de l'onglet Base contacts.

Sheet Fiche prospect
B1: FICHE PROSPECT
B2: Choisissez une ecole dans la liste deroulante : la fiche se remplit toute seule.
B4: Ecole | C4: ABIDJAN BLOOM UNIVERSITY (ABU)
B6: Type d'etablissement | C6: =IFERROR(INDEX('Base contacts'!$B$2:$B$691,MATCH($C$4,'Base contacts'!$A$2:$A$691,0)),"")
B7: Statut | C7: =IFERROR(INDEX('Base contacts'!$C$2:$C$691,MATCH($C$4,'Base contacts'!$A$2:$A$691,0)),"")
B8: Ville / Commune | C8: =IFERROR(INDEX('Base contacts'!$D$2:$D$691,MATCH($C$4,'Base contacts'!$A$2:$A$691,0)),"")
B9: Adresse | C9: =IFERROR(INDEX('Base contacts'!$E$2:$E$691,MATCH($C$4,'Base contacts'!$A$2:$A$691,0)),"")
B11: Telephone 1 | C11: =IFERROR(INDEX('Base contacts'!$F$2:$F$691,MATCH($C$4,'Base contacts'!$A$2:$A$691,0)),"")
B12: Telephone 2 | C12: =IFERROR(INDEX('Base contacts'!$G$2:$G$691,MATCH($C$4,'Base contacts'!$A$2:$A$691,0)),"")
B13: WhatsApp | C13: =IFERROR(INDEX('Base contacts'!$H$2:$H$691,MATCH($C$4,'Base contacts'!$A$2:$A$691,0)),"")
B15: Email | C15: =IFERROR(INDEX('Base contacts'!$I$2:$I$691,MATCH($C$4,'Base contacts'!$A$2:$A$691,0)),"")
B16: Etat de l'adresse | C16: =IFERROR(INDEX('Base contacts'!$O$2:$O$691,MATCH($C$4,'Base contacts'!$A$2:$A$691,0)),"")
B17: Site web | C17: =IFERROR(INDEX('Base contacts'!$J$2:$J$691,MATCH($C$4,'Base contacts'!$A$2:$A$691,0)),"")
B19: Interlocuteur a demander | C19: =IFERROR(INDEX('Base contacts'!$K$2:$K$691,MATCH($C$4,'Base contacts'!$A$2:$A$691,0)),"")
B20: Fiabilite du contact | C20: =IFERROR(INDEX('Base contacts'!$L$2:$L$691,MATCH($C$4,'Base contacts'!$A$2:$A$691,0)),"")
B21: Source | C21: =IFERROR(INDEX('Base contacts'!$M$2:$M$691,MATCH($C$4,'Base contacts'!$A$2:$A$691,0)),"")
B22: Filiere (segment) | C22: =IFERROR(INDEX('Base contacts'!$P$2:$P$691,MATCH($C$4,'Base contacts'!$A$2:$A$691,0)),"")
B24: Accroche WhatsApp a utiliser
B25: =IFERROR(INDEX(Accroches!$C$5:$C$17,MATCH($C$22,Accroches!$B$5:$B$17,0)),"")
B29: Canal recommande
B30: Par quoi commencer | C30: =IF($C$16="sans email","WhatsApp ou telephone : aucune adresse exploitable",IF($C$16="boite pleine","WhatsApp d'abord, la boite e-mail sature",IF($C$16="a verifier","E-mail possible mais adresse jamais testee : doubler par WhatsApp","E-mail puis relance WhatsApp")))
B32: A remplir pendant l'appel
B33: Nom du Directeur des Etudes
B34: Date du 1er contact
B35: Statut
B36: Nb d'eleves annonce
B37: Nb de classes envisage
B38: Date de seance
B39: Notes
B41: Cette fiche ne conserve rien : elle affiche l'ecole choisie. Le suivi se tient dans l'onglet Suivi appels.

Sheet Tableau de bord
B1: TABLEAU DE BORD
B2: Tout se calcule depuis l'onglet Suivi appels. La ligne d'exemple est exclue.
B4: Ecoles dans la base | C4: =COUNTA('Suivi appels'!$B$3:$B$692) | D4: Toutes vagues confondues
B5: Ecoles contactees | C5: =COUNTIFS('Suivi appels'!$I$3:$I$692,"<>A contacter") | D5: Statut different de A contacter
B6: RDV fixes | C6: =COUNTIFS('Suivi appels'!$I$3:$I$692,"RDV fixe")
B7: En negociation | C7: =COUNTIFS('Suivi appels'!$I$3:$I$692,"En negociation")
B8: Ecoles signees | C8: =COUNTIFS('Suivi appels'!$I$3:$I$692,"Signe")
B9: Taux de transformation | C9: =IFERROR(COUNTIFS('Suivi appels'!$I$3:$I$692,"Signe")/COUNTIFS('Suivi appels'!$I$3:$I$692,"<>A contacter"),"") | D9: Signees / contactees
B11: CA signe | C11: =SUMIFS('Suivi appels'!$O$3:$O$692,'Suivi appels'!$I$3:$I$692,"Signe") | D11: Somme des montants attendus au statut Signe
B12: CA en negociation | C12: =SUMIFS('Suivi appels'!$O$3:$O$692,'Suivi appels'!$I$3:$I$692,"En negociation")
B13: CA potentiel total | C13: =SUM('Suivi appels'!$O$3:$O$692) | D13: Tout ce qui est renseigne, tous statuts
B15: Vague 1 - restant a contacter | C15: =COUNTIFS('Suivi appels'!$A$3:$A$692,1,'Suivi appels'!$I$3:$I$692,"A contacter") | D15: Prive Abidjan, contact verifie
B16: Vague 2 - restant a contacter | C16: =COUNTIFS('Suivi appels'!$A$3:$A$692,2,'Suivi appels'!$I$3:$I$692,"A contacter") | D16: Prive, contact a qualifier
B17: Vague 3 - restant a contacter | C17: =COUNTIFS('Suivi appels'!$A$3:$A$692,3,'Suivi appels'!$I$3:$I$692,"A contacter") | D17: Public, circuit long

Sheet Suivi appels
A1: Vague | B1: Ecole | C1: Commune | D1: Telephone | E1: WhatsApp | F1: Email | G1: Nom du Directeur des Etudes | H1: Date 1er contact | I1: Statut | J1: Montant par eleve | K1: Nb eleves par classe | L1: Nb seances negocie | M1: Nb classes | N1: Date seance | O1: Montant attendu (FCFA) | P1: Notes
A2: 1 | B2: EXEMPLE - supprimer cette ligne | C2: Abidjan - Cocody | D2: +225 27 22 00 00 00 | E2: +225 07 00 00 00 00 | F2: exemple@ecole.ci | G2: M. KOUAME | H2: 15/10/2026 | I2: Signe | J2: 5000 | K2: 40 | L2: 2 | M2: 3 | N2: 22/10/2026 | O2: =IF(OR($J2="",$K2="",$M2=""),"",($J2+IF(AND($L2>=2,$J2=5000),3000,0))*$K2*$M2) | P2: 2e seance negociee : +3 000 F/eleve applique automatiquement
A3: 1 | B3: ABIDJAN BLOOM UNIVERSITY (ABU) | C3: Abidjan - Cocody | D3: +225 05 56 35 58 86 | E3: +225 05 56 35 58 86 | F3: infos@abu-ci.com | I3: A contacter | L3: 1 | O3: =IF(OR($J3="",$K3="",$M3=""),"",($J3+IF(AND($L3>=2,$J3=5000),3000,0))*$K3*$M3)
A4: 1 | B4: ABIDJAN BUSINESS SCHOOL (ABS) | C4: Abidjan - Cocody | I4: A contacter | L4: 1 | O4: =IF(OR($J4="",$K4="",$M4=""),"",($J4+IF(AND($L4>=2,$J4=5000),3000,0))*$K4*$M4)
A5: 1 | B5: ACADEMIE DE GESTION ET D'HOTELLERIE (AGH) | C5: Abidjan - Cocody | D5: +225 07 07 33 00 99 | E5: +225 07 07 33 00 99 | F5: agh02@yahoo.fr | I5: A contacter | L5: 1 | O5: =IF(OR($J5="",$K5="",$M5=""),"",($J5+IF(AND($L5>=2,$J5=5000),3000,0))*$K5*$M5)
A6: 1 | B6: ACADEMIE DE L'ENTREPRENEURIAT ET DES METIERS (AEM) YOPOUGON | C6: Abidjan - Yopougon | I6: A contacter | L6: 1 | O6: =IF(OR($J6="",$K6="",$M6=""),"",($J6+IF(AND($L6>=2,$J6=5000),3000,0))*$K6*$M6)
A7: 1 | B7: ACADEMIE DES SCIENCES TECHNOLOGIQUES ET COMPTABLES (ASTC PLATEAU) | C7: Abidjan - Plateau | D7: +225 27 20 32 21 15 | F7: astc2003@yahoo.fr | I7: A contacter | L7: 1 | O7: =IF(OR($J7="",$K7="",$M7=""),"",($J7+IF(AND($L7>=2,$J7=5000),3000,0))*$K7*$M7)
A8: 1 | B8: ACADEMIE DES SCIENCES TECHNOLOGIQUES ET COMPTABLES COCODY (ASTC COCODY) | C8: Abidjan - Cocody | D8: +225 27 22 41 16 11 | F8: astc2plateaux@yahoo.com | I8: A contacter | L8: 1 | O8: =IF(OR($J8="",$K8="",$M8=""),"",($J8+IF(AND($L8>=2,$J8=5000),3000,0))*$K8*$M8)
A9: 1 | B9: ACADEMIE ELITES | C9: Abidjan - Yopougon | D9: +225 27 23 41 94 43 | E9: +225 01 01 44 74 44 | F9: info@academie-elites.com | I9: A contacter | L9: 1 | O9: =IF(OR($J9="",$K9="",$M9=""),"",($J9+IF(AND($L9>=2,$J9=5000),3000,0))*$K9*$M9)
A10: 1 | B10: ACADEMIE FICOGES COCODY | C10: Abidjan - Cocody | D10: +225 27 22 52 58 66 | F10: academieficoges@yahoo.fr | I10: A contacter | L10: 1 | O10: =IF(OR($J10="",$K10="",$M10=""),"",($J10+IF(AND($L10>=2,$J10=5000),3000,0))*$K10*$M10)
A11: 1 | B11: ACADEMIE INTERNATIONALE DES SCIENCES ET TECHNIQUES RIVIERA BONOUMIN (AIST RIVIERA BONOUMIN) | C11: Abidjan - Riviera | D11: +225 27 22 47 36 33 | F11: aistacademie@yahoo.fr | I11: A contacter | L11: 1 | O11: =IF(OR($J11="",$K11="",$M11=""),"",($J11+IF(AND($L11>=2,$J11=5000),3000,0))*$K11*$M11)
A12: 1 | B12: ACADEMIE INTERNATIONALE DES SCIENCES ET TECHNIQUES TREICHVILLE (AIST TREICHVILLE) | C12: Abidjan - Treichville | D12: +225 27 21 24 12 18 | E12: +225 07 07 48 36 18 | F12: aist.treichville1@gmail.com | I12: A contacter | L12: 1 | O12: =IF(OR($J12="",$K12="",$M12=""),"",($J12+IF(AND($L12>=2,$J12=5000),3000,0))*$K12*$M12)
A13: 1 | B13: ACADEMIE LIBRE DE TECHNOLOGIE-INSTITUT SECONDAIRE DE TECHNOLOGIE (ALT-ISTEA YOPOUGON) | C13: Abidjan - Yopougon | D13: +225 01 42 73 72 28 | E13: +225 01 42 73 72 28 | F13: altistea@yahoo.fr | I13: A contacter | L13: 1 | O13: =IF(OR($J13="",$K13="",$M13=""),"",($J13+IF(AND($L13>=2,$J13=5000),3000,0))*$K13*$M13)
A14: 1 | B14: AFRICAN SCHOOL OF ECONOMICS COTE D'IVOIRE (ASE-CI) | C14: Abidjan - Cocody | D14: +225 07 11 01 37 32 | E14: +225 07 11 01 37 32 | F14: aseabidjan@africanschoolofeconomics.com | I14: A contacter | L14: 1 | O14: =IF(OR($J14="",$K14="",$M14=""),"",($J14+IF(AND($L14>=2,$J14=5000),3000,0))*$K14*$M14)
A15: 1 | B15: AFRICAN VISION INSTITUT DE DEVELOPPEMENT ET D'ECONOMIE (AVIDE EDUCATION) | C15: Abidjan - Cocody | D15: +225 27 22 45 66 09 | F15: info@avide-edu.org | I15: A contacter | L15: 1 | O15: =IF(OR($J15="",$K15="",$M15=""),"",($J15+IF(AND($L15>=2,$J15=5000),3000,0))*$K15*$M15)
A16: 1 | B16: AFRIQUE FORMATION | C16: Abidjan - Koumassi | D16: +225 01 51 11 01 57 | E16: +225 01 51 11 01 57 | F16: directionafriqueformation@gmail.com | I16: A contacter | L16: 1 | O16: =IF(OR($J16="",$K16="",$M16=""),"",($J16+IF(AND($L16>=2,$J16=5000),3000,0))*$K16*$M16)
A17: 1 | B17: AGITEL-FORMATION | C17: Abidjan - Cocody Riviera Palmeraie | D17: +225 27 22 23 60 03 | E17: +225 07 89 49 95 65 | F17: infos@agitel-formation.net | I17: A contacter | L17: 1 | O17: =IF(OR($J17="",$K17="",$M17=""),"",($J17+IF(AND($L17>=2,$J17=5000),3000,0))*$K17*$M17)
A18: 1 | B18: AIST Plateau - Academie Internationale des Sciences et Techniques | C18: Abidjan - Plateau | D18: +225 27 20 22 60 20 | E18: +225 05 05 99 45 13 | F18: aistplateau@gmail.com | I18: A contacter | L18: 1 | O18: =IF(OR($J18="",$K18="",$M18=""),"",($J18+IF(AND($L18>=2,$J18=5000),3000,0))*$K18*$M18)
A19: 1 | B19: ALT - ISTEA | C19: Abidjan - Yopougon | D19: +225 27 20 21 13 58 | I19: A contacter | L19: 1 | O19: =IF(OR($J19="",$K19="",$M19=""),"",($J19+IF(AND($L19>=2,$J19=5000),3000,0))*$K19*$M19)
A20: 1 | B20: ATLANTIQUE INTERNATIONAL BUSINESS SCHOOL (AIBS) | C20: Abidjan - Cocody | D20: +225 27 22 44 50 49 | F20: info@atlantique-ibs.net | I20: A contacter | L20: 1 | O20: =IF(OR($J20="",$K20="",$M20=""),"",($J20+IF(AND($L20>=2,$J20=5000),3000,0))*$K20*$M20)
A21: 1 | B21: ATSAM-AGI | C21: Abidjan - Yopougon | D21: +225 27 35 97 06 41 | E21: +225 07 04 29 54 99 | F21: atsam.agi@gmail.com | I21: A contacter | L21: 1 | O21: =IF(OR($J21="",$K21="",$M21=""),"",($J21+IF(AND($L21>=2,$J21=5000),3000,0))*$K21*$M21)
A22: 1 | B22: BA’OULEHN INSTITUTE OF TECHNOLOGIE (BIT ) | C22: Abidjan - Cocody | D22: +225 05 05 59 91 56 | E22: +225 05 05 59 91 56 | F22: baoulehninstitute@gmail.com | I22: A contacter | L22: 1 | O22: =IF(OR($J22="",$K22="",$M22=""),"",($J22+IF(AND($L22>=2,$J22=5000),3000,0))*$K22*$M22)
A23: 1 | B23: BEM Ecole de Banque et de Finance | C23: Abidjan Cocody | D23: +225 27 21 77 67 41 | E23: +225 07 77 49 77 49 | F23: contact@bem.ci | I23: A contacter | L23: 1 | O23: =IF(OR($J23="",$K23="",$M23=""),"",($J23+IF(AND($L23>=2,$J23=5000),3000,0))*$K23*$M23)
A24: 1 | B24: BRITISH INTERNATIONALUNIVERSITY (BIU) | C24: Abidjan - Cocody | D24: +225 27 22 24 63 17 | E24: +225 07 88 20 20 20 | F24: admission@biu.education | I24: A contacter | L24: 1 | O24: =IF(OR($J24="",$K24="",$M24=""),"",($J24+IF(AND($L24>=2,$J24=5000),3000,0))*$K24*$M24)
A25: 1 | B25: CELIA TREICHVILLE/EP2005 | C25: Abidjan - Treichville | I25: A contacter | L25: 1 | O25: =IF(OR($J25="",$K25="",$M25=""),"",($J25+IF(AND($L25>=2,$J25=5000),3000,0))*$K25*$M25)
A26: 1 | B26: CENTRALE SUP (CS) | C26: Abidjan - Cocody | D26: +225 07 77 87 83 93 | E26: +225 07 77 87 83 93 | I26: A contacter | L26: 1 | O26: =IF(OR($J26="",$K26="",$M26=""),"",($J26+IF(AND($L26>=2,$J26=5000),3000,0))*$K26*$M26)
A27: 1 | B27: CENTRE D ENSEIGNEMENT SUPERIEUR ET DES TECHNOLOGIES INTERNATIONALES D'ABIDJAN (CESTIA-2EP) | C27: Abidjan - Cocody | D27: +225 27 22 42 01 66 | F27: infos.groupecestia@gmail.com | I27: A contacter | L27: 1 | O27: =IF(OR($J27="",$K27="",$M27=""),"",($J27+IF(AND($L27>=2,$J27=5000),3000,0))*$K27*$M27)
A28: 1 | B28: CENTRE D'ENSEIGNEMENT TECHNIQUE PROFESSIONNEL DES METIERS ET DE L'ENERGIE RENOUVELABLES (CETPMER) | C28: Abidjan - Adjame | D28: +225 27 20 21 81 21 | E28: +225 01 01 05 11 42 | I28: A contacter | L28: 1 | O28: =IF(OR($J28="",$K28="",$M28=""),"",($J28+IF(AND($L28>=2,$J28=5000),3000,0))*$K28*$M28)
A29: 1 | B29: CENTRE D'ETUDES, DE FORMATION EN INFORMATIQUE ET VISIO ENSEIGNEMENT (CEFIVE) | C29: Abidjan - Cocody | D29: +225 27 22 48 62 82 | F29: cefive@cefive-ci.com | I29: A contacter | L29: 1 | O29: =IF(OR($J29="",$K29="",$M29=""),"",($J29+IF(AND($L29>=2,$J29=5000),3000,0))*$K29*$M29)
A30: 1 | B30: CENTRE DE FORMATION A LA GESTION DES ENTREPRISES DE CÔTE D'IVOIRE (CFGE) | C30: Abidjan - Cocody | D30: +225 05 94 77 50 59 | E30: +225 05 94 77 50 59 | F30: cfgeci01@gmail.com | I30: A contacter | L30: 1 | O30: =IF(OR($J30="",$K30="",$M30=""),"",($J30+IF(AND($L30>=2,$J30=5000),3000,0))*$K30*$M30)
A31: 1 | B31: CENTRE DE FORMATION EN ADMINISTRATION ET EN MECANIQUE (CFAM) | C31: Abidjan - Cocody | D31: +225 07 57 10 74 63 | E31: +225 07 57 10 74 63 | I31: A contacter | L31: 1 | O31: =IF(OR($J31="",$K31="",$M31=""),"",($J31+IF(AND($L31>=2,$J31=5000),3000,0))*$K31*$M31)
A32: 1 | B32: CENTRE DES ETUDES SUPERIEURES DES ETUDES D'ABIDJAN KOUMASSI (CESA KOUMASSI) | C32: Abidjan - Koumassi | D32: +225 27 21 56 31 74 | F32: cofecesa@cofecesa.net | I32: A contacter | L32: 1 | O32: =IF(OR($J32="",$K32="",$M32=""),"",($J32+IF(AND($L32>=2,$J32=5000),3000,0))*$K32*$M32)
A33: 1 | B33: CENTRE DES ETUDES SUPERIEURES DES ETUDES D'ABIDJAN PLATEAU (CESA PLATEAU) | C33: Abidjan - Plateau | D33: +225 27 20 21 97 56 | I33: A contacter | L33: 1 | O33: =IF(OR($J33="",$K33="",$M33=""),"",($J33+IF(AND($L33>=2,$J33=5000),3000,0))*$K33*$M33)
A34: 1 | B34: CENTRE DES ETUDES SUPERIEURES DES ETUDES D'ABIDJAN YOPOUGON (CESA YOPOUGON) | C34: Abidjan - Yopougon | D34: +225 25 23 00 33 88 | E34: +225 07 49 38 33 40 | F34: alain_achi@yahoo.fr | I34: A contacter | L34: 1 | O34: =IF(OR($J34="",$K34="",$M34=""),"",($J34+IF(AND($L34>=2,$J34=5000),3000,0))*$K34*$M34)
A35: 1 | B35: CENTRE INTERNATIONAL DE FORMATION EN PRESENTIELLE ET A DISTANCE COCODY (CIFAD COCODY) | C35: Abidjan - Cocody | F35: rusta.cifad@gmail.com | I35: A contacter | L35: 1 | O35: =IF(OR($J35="",$K35="",$M35=""),"",($J35+IF(AND($L35>=2,$J35=5000),3000,0))*$K35*$M35)
A36: 1 | B36: CENTRE INTERNATIONAL DE FORMATION EN PRESENTIELLE ET A DISTANCE YOPOUGON (CIFAD YOPOUGON) | C36: Abidjan - Yopougon | F36: rusta.cifad@gmail.com | I36: A contacter | L36: 1 | O36: =IF(OR($J36="",$K36="",$M36=""),"",($J36+IF(AND($L36>=2,$J36=5000),3000,0))*$K36*$M36)
A37: 1 | B37: CENTRE INTERNATIONAL DU MANAGEMENT ET DE L'ENTREPRENEURIAT (CIME-FORMATION ABIDJAN) | C37: Abidjan - Cocody | D37: +225 27 22 52 87 80 | F37: ecime.formation@yahoo.fr | I37: A contacter | L37: 1 | O37: =IF(OR($J37="",$K37="",$M37=""),"",($J37+IF(AND($L37>=2,$J37=5000),3000,0))*$K37*$M37)
A38: 1 | B38: CFOMIS | C38: Abidjan Yopougon | D38: +225 27 23 48 90 95 | E38: +225 07 67 65 17 67 | F38: infos@cfomis-ci.com | I38: A contacter | L38: 1 | O38: =IF(OR($J38="",$K38="",$M38=""),"",($J38+IF(AND($L38>=2,$J38=5000),3000,0))*$K38*$M38)
A39: 1 | B39: CHANTIERS ECOLE DES METIERS DU BATIMENT ET DES TRAVAUX PUBLICS (CEM-BTP COCODY) | C39: Abidjan - Cocody | D39: +225 27 22 40 40 07 | E39: +225 07 07 54 77 48 | I39: A contacter | L39: 1 | O39: =IF(OR($J39="",$K39="",$M39=""),"",($J39+IF(AND($L39>=2,$J39=5000),3000,0))*$K39*$M39)
A40: 1 | B40: CIFC ABIDJAN | C40: Abidjan - Cocody | F40: abidjancifc@gmail.com | I40: A contacter | L40: 1 | O40: =IF(OR($J40="",$K40="",$M40=""),"",($J40+IF(AND($L40>=2,$J40=5000),3000,0))*$K40*$M40)
...

Sheet Base contacts
A1: Ecole | B1: Type | C1: Statut | D1: Ville / Commune | E1: Adresse | F1: Telephone 1 | G1: Telephone 2 | H1: WhatsApp | I1: Email | J1: Site web | K1: Interlocuteur cible | L1: Fiabilite | M1: Source | N1: Type email | O1: Etat email | P1: Segment
A2: ECOFORP-A INTERNATIONALE | B2: Grande ecole BTS - agriculture tropicale, finances comptabilite, gestion commerciale | C2: Prive | D2: Abengourou | E2: QUARTIER PLATEAU, ANCIEN LOCAUX DE L ONUCI PRES DE LA PREFECTURE DE POLICE | F2: +225 07 09 22 47 24 | G2: +225 01 72 25 39 82 | H2: +225 07 09 22 47 24 | I2: ecoforp@gmail.com | J2: https://ecoforp.com | K2: Directeur des Etudes | L2: Haute | M2: MESRS - liste officielle grandes ecoles | N2: gratuite | O2: a verifier | P2: commerce
A3: ECOLE SUPERIEURE DE COMMERCE D'ABENGOUROU (ESC ABENGOUROU) | B3: Grande ecole BTS - assistanat de direction, agriculture tropicale, finances comptabilite | C3: Prive | D3: Abengourou | E3: ABENGOUROU, QUARTIER PLATEAU, RUE BCEAO | F3: +225 27 35 91 43 82 | I3: malkom01@yahoo.fr | K3: Directeur des Etudes | L3: Haute | M3: MESRS - liste officielle grandes ecoles | N3: gratuite | O3: a verifier | P3: commerce
A4: GROUPE ONYX EXCELLENCE ABENOUROU (GOEA) | B4: Grande ecole BTS - assistanat de direction, finances comptabilite, gestion commerciale | C4: Prive | D4: Abengourou | F4: +225 07 07 31 36 17 | H4: +225 07 07 31 36 17 | K4: Directeur des Etudes | L4: Haute | M4: MESRS - liste officielle grandes ecoles | O4: sans email | P4: commerce
A5: IESTP ABENGOUROU | B5: Grande ecole BTS - assistanat de direction, agriculture tropicale, finances comptabilite | C5: Prive | D5: Abengourou | E5: ABENGOUROU PRES DU COLLEGE REINE NOUFAN | F5: +225 01 03 36 01 10 | G5: +225 07 07 89 73 78 | H5: +225 01 03 36 01 10 | I5: abengiestpa@gmail.com | J5: https://htps://www.iestpabengourou.net | K5: Directeur des Etudes | L5: Haute | M5: MESRS - liste officielle grandes ecoles | N5: gratuite | O5: a verifier | P5: commerce
A6: ESTEAI - Ecole Superieure des Techniques Electroniques Audiovisuelles et Informatiques | B6: Ecole superieure - electronique et informatique | C6: Prive | D6: Abidjan | E6: Abidjan | F6: +225 05 75 26 03 53 | I6: info@esteai.com | J6: https://www.esteai.com | K6: Directeur des Etudes | L6: Haute | M6: AnnuaireCI + MESRS | N6: domaine propre | O6: a verifier | P6: numerique
A7: INFAS Institut National de Formation des Agents de Sante | B7: Institut national - sante paramedical infirmiers sages-femmes | C7: Public | D7: Abidjan | F7: +225 07 87 88 99 02 | G7: +225 05 64 87 80 70 | J7: https://infas.ci | K7: Directeur des Etudes | L7: Moyenne | M7: edukiya.com | O7: sans email | P7: sante
A8: ECOLE DE FORMATION EN GESTION ET EN TECHNOLOGIE (EFGT ABIDJAN) | B8: Grande ecole BTS - assistanat de direction, communication visuelle, finances comptabilite | C8: Prive | D8: Abidjan - Abobo | F8: +225 27 24 52 00 14 | G8: +225 05 05 35 25 29 | H8: +225 05 05 35 25 29 | I8: efgt.info@gmail.com | K8: Directeur des Etudes | L8: Haute | M8: MESRS - liste officielle grandes ecoles | N8: gratuite | O8: a verifier | P8: numerique
A9: ECOLE DES NUMERIQUES, DE L'ADMINISTRATION ET DE TELECOMMUNICATION ABOBO (ENATEL) | B9: Grande ecole BTS - electrotechnique, finances comptabilite, genie civil | C9: Prive | D9: Abidjan - Abobo | E9: EBIMPE, non loin Stade Olympique , Dans la cité Olympe | F9: +225 07 08 41 53 42 | G9: +225 07 48 77 48 77 | H9: +225 07 08 41 53 42 | I9: enatel2022@gmail.com | K9: Directeur des Etudes | L9: Haute | M9: MESRS - liste officielle grandes ecoles | N9: gratuite | O9: a verifier | P9: communication
A10: ECOLE SUPERIEURE INTERNATIONALE POLYTECHNIQUE ADAMA SANOGO (ESIAS) | B10: Grande ecole BTS - assistanat de direction, communication visuelle, electrotechnique | C10: Prive | D10: Abidjan - Abobo | E10: PLATEAU DOKUI | F10: +225 07 47 00 00 49 | G10: +225 07 07 88 78 04 | H10: +225 07 47 00 00 49 | I10: tchomba@hotmail.fr | J10: http:/www.groupeadamasanogo.com | K10: Directeur des Etudes | L10: Haute | M10: MESRS - liste officielle grandes ecoles | N10: gratuite | O10: a verifier | P10: ingenieur
A11: ECOLE SUPERIEURE LE PETIT CHAMPION (ESPC) | B11: Grande ecole BTS - assistanat de direction, finances comptabilite, genie civil | C11: Prive | D11: Abidjan - Abobo | E11: ABOBO QUARTIER SAGBE DERRIERE RAIL | F11: +225 07 07 04 73 11 | H11: +225 07 07 04 73 11 | I11: ecolesup.lepetitchampion@gmail.com | K11: Directeur des Etudes | L11: Haute | M11: MESRS - liste officielle grandes ecoles | N11: gratuite | O11: a verifier | P11: commerce
A12: ECOLE TECHNIQUE INFORMATIQUE ET COMMERCIALE ABOBO (ETIC ABOBO) | B12: Grande ecole BTS - assistanat de direction, agriculture tropicale, communication visuelle | C12: Prive | D12: Abidjan - Abobo | F12: +225 27 22 41 54 06 | G12: +225 05 05 79 02 20 | H12: +225 05 05 79 02 20 | K12: Directeur des Etudes | L12: Haute | M12: MESRS - liste officielle grandes ecoles | O12: sans email | P12: numerique
A13: ETEP Abobo - Ecole Technique et Professionnelle | B13: Grande ecole - BTS tertiaire et industriel | C13: Prive | D13: Abidjan - Abobo | E13: Autoroute Banco entre la Coopec et le College Saint Joseph Abobo | F13: +225 27 20 21 35 23 | G13: +225 01 02 20 59 34 | H13: +225 01 40 89 06 61 | I13: etep01abobo@gmail.com | J13: https://www.groupetep.org/ | K13: Directeur des Etudes (par campus) | L13: Haute | M13: UPESUP + MESRS | N13: gratuite | O13: a verifier | P13: ingenieur
A14: ETIC Abobo - Ecole Technique Informatique et Commerciale | B14: Ecole superieure technique - informatique et commerce | C14: Prive | D14: Abidjan - Abobo | F14: +225 07 07 24 63 15 | H14: +225 07 07 24 63 15 | J14: eticecole.com | K14: Directeur des Etudes (par campus) | L14: Moyenne | M14: Le Grand Frere | O14: sans email | P14: numerique
A15: GESTPCI - Groupe d'Enseignement Superieur Technique et Professionnel de Cote d'Ivoire | B15: Grande ecole - tertiaire et industriel | C15: Prive | D15: Abidjan - Abobo | E15: Abobo-Anador Cocoteraie | F15: +225 07 59 74 39 10 | G15: +225 07 08 34 14 67 | H15: +225 07 59 74 39 10 | I15: infos24gestpci@gmail.com | J15: gestpci.com | K15: Directeur des Etudes | L15: Haute | M15: Site officiel gestpci.com + MESRS | N15: gratuite | O15: a verifier | P15: ingenieur
A16: GROUPE CONCORDET N'DOTRE (ESGTC N'DOTRE) | B16: Grande ecole BTS - finances comptabilite, genie civil, gestion commerciale | C16: Prive | D16: Abidjan - Abobo | K16: Directeur des Etudes | L16: Haute | M16: MESRS - liste officielle grandes ecoles | O16: sans email | P16: commerce
A17: GROUPE D ENSEIGNEMENT SUPERIEUR ET PROFESSIONNEL D AGBE (GESSP) | B17: Grande ecole BTS - finances comptabilite, gestion commerciale, informatique developpeur d'applications | C17: Prive | D17: Abidjan - Abobo | E17: ABOBO PK18 | F17: +225 01 01 05 35 63 | G17: +225 07 07 83 78 76 | H17: +225 01 01 05 35 63 | I17: gesspci2020@gmail.com | K17: Directeur des Etudes | L17: Haute | M17: MESRS - liste officielle grandes ecoles | N17: gratuite | O17: a verifier | P17: commerce
A18: HETEC ABOBO (HETEC ABIDJAN) | B18: Grande ecole BTS - assistanat de direction, electrotechnique, finances comptabilite | C18: Prive | D18: Abidjan - Abobo | E18: ABOBO, PLATEAU DOKUI, 1er arrêt Dokui, derrière la Cité Forest | F18: +225 27 24 01 00 82 | I18: info@groupehetec.com | J18: http://www.groupehetec.net | K18: Directeur des Etudes | L18: Haute | M18: MESRS - liste officielle grandes ecoles | N18: domaine propre | O18: a verifier | P18: commerce
A19: I2SMA | B19: Grande ecole BTS - assistanat de direction, finances comptabilite, gestion commerciale | C19: Prive | D19: Abidjan - Abobo | E19: ANYAMA QUARTIER ZOSSONKOI | F19: +225 27 23 55 93 45 | K19: Directeur des Etudes | L19: Haute | M19: MESRS - liste officielle grandes ecoles | O19: sans email | P19: commerce
A20: INSTITUT DE FORMATION SAINTE MARIE ABOBO BAOULE (IFSM ABOBO BAOULE) | B20: Grande ecole BTS - electrotechnique, finances comptabilite, gestion commerciale | C20: Prive | D20: Abidjan - Abobo | E20: ABOBO BAOULE carrefour garage fofana route belleville | F20: +225 25 20 00 16 71 | G20: +225 05 94 55 09 17 | H20: +225 05 94 55 09 17 | K20: Directeur des Etudes | L20: Haute | M20: MESRS - liste officielle grandes ecoles | O20: sans email | P20: commerce
A21: INSTITUT DE FORMATION SAINTE MARIE ABOBO CAMP COMMANDO (IFSM ABOBO CAMP COMMANDO) | B21: Grande ecole BTS - assistanat de direction, communication visuelle, finances comptabilite | C21: Prive | D21: Abidjan - Abobo | E21: ABOBO Route Camp Commando Après l'école primaire 3 chatons | F21: +225 25 21 00 55 66 | G21: +225 05 94 55 09 17 | H21: +225 05 94 55 09 17 | I21: ifsmabobo@yahoo.fr | J21: http://www.ifsm.ci | K21: Directeur des Etudes | L21: Haute | M21: MESRS - liste officielle grandes ecoles | N21: gratuite | O21: a verifier | P21: commerce
A22: INSTITUT DE FORMATION SAINTE MARIE ABOBO MARAHOUE (IFSM ABOBO MARAHOUE) | B22: Grande ecole BTS - agriculture tropicale, electrotechnique, finances comptabilite | C22: Prive | D22: Abidjan - Abobo | E22: ABOBO AVOCATIER | F22: +225 25 24 00 05 95 | G22: +225 05 94 55 09 17 | H22: +225 05 94 55 09 17 | K22: Directeur des Etudes | L22: Haute | M22: MESRS - liste officielle grandes ecoles | O22: sans email | P22: commerce
A23: INSTITUT DE TECHNOLOGIE AURELS (IT AURELS) | B23: Grande ecole BTS - assistanat de direction, electrotechnique, finances comptabilite | C23: Prive | D23: Abidjan - Abobo | E23: Abobo PK 18 Cité Concorde | F23: +225 05 75 86 83 83 | G23: +225 07 48 58 85 31 | H23: +225 05 75 86 83 83 | I23: direction@aurels.org | J23: https://www.aurels.org | K23: Directeur des Etudes | L23: Haute | M23: MESRS - liste officielle grandes ecoles | N23: domaine propre | O23: a verifier | P23: numerique
A24: INSTITUT DES TECHNOLOGIES D'ABIDJAN (ITA ABOBO) | B24: Grande ecole BTS - finances comptabilite, gestion commerciale, informatique developpeur d'applications | C24: Prive | D24: Abidjan - Abobo | K24: Directeur des Etudes | L24: Haute | M24: MESRS - liste officielle grandes ecoles | O24: sans email | P24: numerique
A25: INSTITUT INTERNATIONAL POLYTECHNIQUE DES ELITES D'ABIDJAN (IIPEA ABOBO) | B25: Grande ecole BTS - assistanat de direction, finances comptabilite, gestion commerciale | C25: Prive | D25: Abidjan - Abobo | E25: Abobo Carrefour Mairie non loin de la Gare | F25: +225 07 01 88 58 16 | G25: +225 07 01 58 78 28 | H25: +225 07 01 88 58 16 | I25: secretariat@iipea.com | J25: https://www.iipea.com | K25: Directeur des Etudes | L25: Haute | M25: MESRS - liste officielle grandes ecoles | N25: domaine propre | O25: a verifier | P25: ingenieur
A26: INSTITUT SUPERIEUR DE COMMERCE ET DE MANAGEMENT MAERIFA (ISCM MAERIFA) | B26: Grande ecole BTS - assistanat de direction, agriculture tropicale, communication visuelle | C26: Prive | D26: Abidjan - Abobo | E26: ABOBO DOKUI EXTENSION, CARREFOUR SODEPLAM (ANADER) | F26: +225 05 05 04 02 24 | H26: +225 05 05 04 02 24 | I26: dkoumba2009@yahoo.fr | K26: Directeur des Etudes | L26: Haute | M26: MESRS - liste officielle grandes ecoles | N26: gratuite | O26: a verifier | P26: commerce
A27: INSTITUT SUPERIEUR DE FORMATION APPLIQUEE (ISFA) | B27: Grande ecole BTS - assistanat de direction, agriculture tropicale, finances comptabilite | C27: Prive | D27: Abidjan - Abobo | E27: ABOBO Avocatier prêt du 32ième arrondissement | F27: +225 07 57 13 68 00 | G27: +225 07 13 23 64 19 | H27: +225 07 57 13 68 00 | I27: isfa.institutsuperieur@gmail.com | K27: Directeur des Etudes | L27: Haute | M27: MESRS - liste officielle grandes ecoles | N27: gratuite | O27: a verifier | P27: commerce
A28: INSTITUT SUPERIEUR DE FORMATION POUR LE DEVELOPPEMENT DES COMPETENCES (ISDEC) | B28: Grande ecole BTS - assistanat de direction, electrotechnique, finances comptabilite | C28: Prive | D28: Abidjan - Abobo | E28: ABOBO SOGEFIA EN FACE DU CAMP COMMANDO | F28: +225 07 58 16 42 16 | G28: +225 07 07 21 51 59 | H28: +225 07 58 16 42 16 | I28: isdecabobo@gmail.com | K28: Directeur des Etudes | L28: Haute | M28: MESRS - liste officielle grandes ecoles | N28: gratuite | O28: a verifier | P28: commerce
A29: INSTITUT SUPERIEUR EZ (IS- EZ) | B29: Grande ecole BTS - finances comptabilite, gestion commerciale, informatique developpeur d'applications | C29: Prive | D29: Abidjan - Abobo | E29: Abobo, entre la Pharmacie Maténé et le Camp Commando | F29: +225 27 22 41 73 90 | I29: institutsup2ez@gmail.com | K29: Directeur des Etudes | L29: Haute | M29: MESRS - liste officielle grandes ecoles | N29: gratuite | O29: a verifier | P29: commerce
A30: INSTITUT SUPERIEUR POLYTECHNIQUE ROOSEVELT (ISPR) | B30: Grande ecole BTS - assistanat de direction, finances comptabilite, genie civil | C30: Prive | D30: Abidjan - Abobo | E30: ABOBO AKEKOI, NON LOIN DE L EGLISE CATHOLIQUE SAINT MARC | F30: +225 07 08 19 23 82 | G30: +225 05 56 56 59 75 | H30: +225 07 08 19 23 82 | I30: institut.ispr@gmail.com | J30: https://www.institutroosevelt.com | K30: Directeur des Etudes | L30: Haute | M30: MESRS - liste officielle grandes ecoles | N30: gratuite | O30: a verifier | P30: ingenieur
A31: INSTITUT SUPERIEUR PROFESSIONNEL (ISP) | B31: Grande ecole BTS - assistanat de direction, agriculture tropicale, electrotechnique | C31: Prive | D31: Abidjan - Abobo | E31: ABOBO COLATIER EN FACE DE LA CITE UNIVERSITAIRE ABOBO 1 | F31: +225 07 77 77 45 43 | H31: +225 07 77 77 45 43 | K31: Directeur des Etudes | L31: Haute | M31: MESRS - liste officielle grandes ecoles | O31: sans email | P31: commerce
A32: INSTITUT SUPERIEUR SAINT CYRILLE (I2SC ABOBO) | B32: Grande ecole BTS - assistanat de direction, finances comptabilite, gestion commerciale | C32: Prive | D32: Abidjan - Abobo | E32: N’DOTRE A LA BOUTIQUE | F32: +225 05 00 98 69 92 | H32: +225 05 00 98 69 92 | I32: isscsup@gmail.com | K32: Directeur des Etudes | L32: Haute | M32: MESRS - liste officielle grandes ecoles | N32: gratuite | O32: a verifier | P32: commerce
A33: INSTITUT SUPERIEUR SAINT JAURES (IS2J) | B33: Grande ecole BTS - finances comptabilite, gestion commerciale, ressources humaines | C33: Prive | D33: Abidjan - Abobo | E33: ABOBO ROUTE DU ZOO, CARREFOUR MAURITANIEN PRES DU CENTRE DE GESTION INTEGRE (CGI)POUR LES PERMIS DE CONDUIRE. | F33: +225 05 76 72 50 50 | G33: +225 01 40 45 09 77 | H33: +225 05 76 72 50 50 | I33: isjeanjaures@gmail.com | J33: https://is2j.ci | K33: Directeur des Etudes | L33: Haute | M33: MESRS - liste officielle grandes ecoles | N33: gratuite | O33: a verifier | P33: commerce
A34: INSTITUT SUPERIEUR SAINTE FOI ABIDJAN (ISSF ABIDJAN) | B34: Grande ecole BTS - assistanat de direction, finances comptabilite, gestion commerciale | C34: Prive | D34: Abidjan - Abobo | E34: ABOBO AVOCATIER | F34: +225 27 24 39 27 41 | I34: groupesaintefoi@gmail.com | K34: Directeur des Etudes | L34: Haute | M34: MESRS - liste officielle grandes ecoles | N34: gratuite | O34: a verifier | P34: commerce
A35: INSTITUT SUPÉRIEUR ADAM MARSHALL ABOBO (ISAM ANNEXE ABOBO) | B35: Grande ecole BTS - assistanat de direction, finances comptabilite, gestion commerciale | C35: Prive | D35: Abidjan - Abobo | E35: ABOBO , route de B.C, Après le camp commando, près de la direction générale des impôt | F35: +225 27 20 22 68 91 | I35: infoadammarshall@gmail.com | J35: https:www.iam-isam.net | K35: Directeur des Etudes | L35: Haute | M35: MESRS - liste officielle grandes ecoles | N35: gratuite | O35: a verifier | P35: commerce
A36: ITP CERIN DOKUI | B36: Grande ecole BTS - finances comptabilite, gestion commerciale, informatique developpeur d'applications | C36: Prive | D36: Abidjan - Abobo | F36: +225 01 02 55 55 50 | H36: +225 01 02 55 55 50 | K36: Directeur des Etudes | L36: Haute | M36: MESRS - liste officielle grandes ecoles | O36: sans email | P36: commerce
A37: LEGACY INSTITUTE | B37: Grande ecole BTS - finances comptabilite, genie civil, gestion commerciale | C37: Prive | D37: Abidjan - Abobo | E37: PLATEAU DOKOUI FACE AU BUREAU DE LA SODECI | F37: +225 27 20 21 54 13 | G37: +225 27 20 22 95 47 | H37: +225 07 07 52 27 43 | K37: Directeur des Etudes | L37: Haute | M37: MESRS - liste officielle grandes ecoles | O37: sans email | P37: commerce
A38: Groupe HETEC | B38: Grande ecole - technologie / commerce | C38: Prive | D38: Abidjan - Abobo Plateau Dokui | E38: 01 BP 4389 Abidjan 01, derriere la Cite Forest | F38: +225 25 24 01 00 82 | G38: +225 07 48 55 43 36 | H38: +225 01 03 51 70 89 | I38: info@groupehetec.net | J38: www.hetec.ci | K38: Directeur des Etudes | L38: Moyenne | M38: Le Grand Frere + Annuaire Pratik | email : Le Grand Frere + Edukiya - domaine .net en service | N38: domaine propre | O38: a verifier | P38: numerique
A39: CENTRE D'ENSEIGNEMENT TECHNIQUE PROFESSIONNEL DES METIERS ET DE L'ENERGIE RENOUVELABLES (CETPMER) | B39: Grande ecole BTS - agriculture tropicale, finances comptabilite, genie civil | C39: Prive | D39: Abidjan - Adjame | F39: +225 27 20 21 81 21 | G39: +225 01 01 05 11 42 | H39: +225 01 01 05 11 42 | K39: Directeur des Etudes | L39: Haute | M39: MESRS - liste officielle grandes ecoles | O39: sans email | P39: commerce
A40: HOREB BUSINESS AND FINANCE ET INSTITUT VICTOR HUGO D ABIDJAN (IVHA) | B40: Grande ecole BTS - finances comptabilite, gestion commerciale, informatique developpeur d'applications | C40: Prive | D40: Abidjan - Adjame | E40: ADJAME EXTENSION RUE N ZIKLI | F40: +225 07 59 86 41 54 | G40: +225 27 20 37 01 25 | H40: +225 07 59 86 41 54 | K40: Directeur des Etudes | L40: Haute | M40: MESRS - liste officielle grandes ecoles | O40: sans email | P40: commerce
...

Sheet Offre et tarifs
B1: OFFRE - INITIATION A L'INTELLIGENCE ARTIFICIELLE
B2: Prestation de base : UNE seance de 2h par classe. La 2e seance se negocie, elle n'est jamais promise d'emblee.
B3: Aucun suivi individuel, aucun groupe WhatsApp : l'interlocuteur est l'etablissement, pas l'eleve.
B5: Les deux paliers
B6: Montant par eleve | C6: Prestation de base | D6: 2e seance
B7: 5000 | C7: 1 seance de 2h + kit + attestation | D7: Facturee +3 000 F par eleve
B8: 10000 | C8: 1 seance de 2h + kit + attestation | D8: Incluable si la classe fait 40 eleves ou plus
B9: Les deux montants ci-dessus sont en bleu : ce sont les seules valeurs a modifier. Le tableau ci-dessous se recalcule.
B11: Chiffre d'affaires par classe, pour 2h de presence
B12: Effectif de la classe | C12: A 5 000 F par eleve | D12: A 10 000 F par eleve
B13: 25 | C13: =$B13*$B$7 | D13: =$B13*$B$8
B14: 40 | C14: =$B14*$B$7 | D14: =$B14*$B$8
B15: 60 | C15: =$B15*$B$7 | D15: =$B15*$B$8
B16: 100 | C16: =$B16*$B$7 | D16: =$B16*$B$8
B17: 5 classes de 40 eleves | C17: =5*40*$B$7 | D17: =5*40*$B$8
B18: Le volume vient du NOMBRE DE CLASSES, jamais du nombre de seances.
B20: Regles de negociation a tenir
B21: 1. | C21: Annoncer une seance. Une seule. Si on en annonce deux, on n'a plus rien a donner en negociation et on a divise le prix horaire par deux pour rien.
B22: 2. | C22: La 2e seance ne se donne jamais contre rien. Elle s'echange contre un engagement sur 3 classes, un paiement integral d'avance, ou des dates bloquees et signees.
B23: 3. | C23: Toujours presenter 10 000 F en premier, puis 5 000 F comme repli. Dans l'autre sens, aucun etablissement ne monte.
B24: 4. | C24: Seuil minimum : 20 eleves payants. En dessous, proposer de regrouper deux classes de la meme filiere dans la meme salle.
B25: 5. | C25: Encaissement : 100 % avant la seance, ou 50 % a la reservation et 50 % a l'arrivee. Jamais de seance entierement a credit.
B26: 6. | C26: Classe pilote a 5 000 F uniquement si l'etablissement s'engage par ecrit sur 3 classes supplementaires le meme mois.
B29: Contenu de la seance (2h)
B30: 15 min | C30: Ce qu'est vraiment l'IA, sans jargon
B31: 20 min | C31: Demo live : un devoir et un expose traites devant la classe
B32: 40 min | C32: Atelier encadre : chaque eleve fait tourner ses premiers prompts sur son telephone
B33: 15 min | C33: Cas d'usage propres a leur filiere
B34: 15 min | C34: Les 5 pieges : hallucination, plagiat, dependance, donnees personnelles, triche
B35: 10 min | C35: IA et employabilite : CV, lettre de motivation, preparation d'entretien
B36: 5 min | C36: Remise des attestations
B38: 2e seance - uniquement si negociee
B39: 35 min | C39: Rediger un rapport de stage ou un memoire avec l'IA sans tomber dans le plagiat
B40: 40 min | C40: Atelier sur un vrai sujet donne par le professeur, de la recherche au plan detaille
B41: 25 min | C41: Verifier une reponse d'IA : la methode en 3 controles
B42: 20 min | C42: Les outils gratuits accessibles depuis la Cote d'Ivoire et leurs limites
B44: Materiel demande a l'ecole : une salle, un videoprojecteur, une prise. Les eleves utilisent leur telephone.

Sheet Scripts et objections
B1: SCRIPTS D'APPROCHE - DIRECTEURS DES ETUDES
B3: 1. WhatsApp (premier contact, le plus efficace en CI)
C4: Bonjour Monsieur/Madame,
C5: Je suis [NOM], de BIG REUSSITE. Je m'adresse a vous en tant que Directeur des Etudes de [ECOLE].
C6: Nous animons des sessions d'initiation a l'intelligence artificielle directement dans les classes : une seance pratique de 2h, avec les telephones des eleves, sans besoin de salle informatique.
C7: L'objectif est simple : que vos etudiants de [FILIERE] sachent utiliser l'IA pour leurs travaux et pour leur employabilite, au lieu de la subir.
C8: Puis-je vous envoyer le programme en 1 page ? Et seriez-vous disponible 15 minutes cette semaine pour en parler ?
C9: Cordialement, [NOM] - [TELEPHONE]
C10: Regle : un seul message. Relance a J+2, puis a J+7, puis on arrete.
B12: 2. Appel au standard (quand on n'a que le fixe)
C13: Bonjour, [NOM] de BIG REUSSITE. Je souhaite joindre le Directeur des Etudes, s'il vous plait. C'est au sujet d'un programme d'initiation a l'IA pour vos classes de BTS.
C14: Si indisponible : Pouvez-vous me donner son numero direct ou son WhatsApp ? Je lui envoie le programme, il verra en 2 minutes si ca l'interesse.
C15: Noter immediatement son nom dans la colonne Nom du Directeur des Etudes de l'onglet Suivi appels.
B17: 3. E-mail (trace formelle, apres le WhatsApp)
C18: Objet : Initiation a l'IA pour vos classes - une seance de 2h par classe
C19: Madame, Monsieur le Directeur des Etudes,
C20: BIG REUSSITE propose aux grandes ecoles de Cote d'Ivoire un module court d'initiation a l'intelligence artificielle, concu pour les etudiants et anime en presentiel dans vos locaux.
C21: Format : une seance de 2h par classe. Materiel : telephones des etudiants et un videoprojecteur. Livrable : kit de prompts et attestation de participation.
C22: Le module couvre l'usage professionnel de l'IA, les cas d'usage propres a chaque filiere, et les regles d'usage responsable, un point que beaucoup d'etablissements souhaitent aujourd'hui cadrer aupres de leurs etudiants.
C23: Je me tiens a votre disposition pour vous presenter le programme detaille et convenir d'un creneau test sur une classe.
C24: Cordialement, [NOM] - BIG REUSSITE - [TELEPHONE] - [EMAIL]
B26: 4. Objections qui reviennent
B27: Objection | C27: Reponse
B28: On n'a pas de salle informatique | C28: Pas necessaire. Les etudiants travaillent sur leur telephone. Il faut juste une salle et un videoprojecteur.
B29: Ce n'est pas au programme officiel | C29: C'est un module hors cursus, sur un creneau libre ou un samedi. Aucune modification de maquette, aucune validation ministerielle requise.
B30: Qui paie ? | C30: L'etablissement fixe une somme par eleve et la collecte, via les frais annexes ou via les delegues de classe. On ne facture qu'une fois la classe confirmee.
B31: Une seule seance, ca suffit ? | C31: La seance est autonome : a la fin, chaque etudiant a fait tourner l'outil lui-meme et repart avec son kit. Une 2e seance est possible, on en discute une fois la premiere programmee. Ne jamais l'offrir a ce stade.
B32: C'est cher pour nos etudiants | C32: Descendre le montant par eleve de 10 000 a 5 000, jamais le nombre de seances ni le seuil de 20 eleves. Et ne descendre qu'en echange d'un engagement sur d'autres classes.
B34: 5. Rythme
C35: 15 contacts WhatsApp par jour sur la vague 1, relance a J+2 puis J+7, puis on passe a la vague suivante. Renseigner le nom du Directeur des Etudes a chaque appel : c'est cette colonne qui fera la valeur de la base dans un mois.

Sheet Accroches
B1: ACCROCHES PAR FILIERE
B2: Lue par la fiche prospect. Une ligne par segment de filiere.
B4: Segment | C4: Accroche WhatsApp | D4: Travaux rendus
B5: agro | C5: Vos étudiants rendent déjà des analyses de données produites par une IA. Sans savoir ce qu'elles valent. | D5: un rapport de stage ou un mémoire technique
B6: btp | C6: Vos étudiants recopient déjà des notes de calcul sorties d'une IA. Sans les refaire. | D6: un rapport de chantier, un métré ou une note de calcul
B7: commerce | C7: Vos étudiants rendent déjà des études de marché avec des chiffres inventés par une IA. Et ils ne le savent même pas. | D7: une étude de marché, un business plan ou un rapport de stage
B8: communication | C8: Vos étudiants produisent déjà leurs dossiers avec une IA. Sans se douter de ce que ça pose comme problème de droits. | D8: un dossier de production ou un mémoire
B9: defaut | C9: Vos étudiants rendent déjà des travaux écrits par une IA. Vos enseignants le voient sans pouvoir le prouver. | D9: un exposé ou un rapport de stage
B10: formation | C10: Vos apprenants utilisent déjà l'IA tous les jours. Aucun ne sait s'en servir pour le métier qu'il vise. | D10: un projet de fin de formation ou un rapport de stage
B11: hotellerie | C11: Vos étudiants rédigent déjà leurs rapports de stage avec une IA. Et ils ne savent pas s'en servir pour le métier qui les attend. | D11: un rapport de stage ou un projet d'établissement
B12: ingenieur | C12: Vos étudiants rendent déjà des notes techniques écrites par une IA. Sans savoir refaire le calcul qu'il y a derrière. | D12: un rapport de projet ou une note technique
B13: logistique | C13: Vos étudiants rendent déjà des études de flux dont les chiffres sortent d'une IA. Chiffres que personne n'a contrôlés. | D13: une étude de cas transport ou un rapport de stage
B14: lycee | C14: Vos élèves rendent déjà des exposés écrits par une IA. Vos enseignants le voient sans pouvoir le prouver. | D14: un exposé ou un dossier de projet
B15: numerique | C15: Vos étudiants livrent déjà du code écrit par une IA. La plupart seraient incapables de l'expliquer devant un jury. | D15: un rapport de projet ou une documentation technique
... B17: universite | C17: Vos étudiants rendent déjà des exposés et des mémoires écrits par une IA. Vos enseignants le voient sans pouvoir le prouver. | D17: un exposé, un rapport de stage ou un mémoire
